Workbook

Sheet Summary
A1: Accrued Commissions - Unclaimed Property Exposure by Entity
A2: Source: United_Cash_Requirements.xlsx, each entity tab, 'Previous Month's Accrued Commissions' block (deposited checks not yet booked in Sage) plus the current-month 'Deposited checks' block. Extracted 10/6/2026; every entity total ties to the tab's 'outstanding amount' cell. Legend: blue = input, black = formula, green = link to another sheet, yellow fill = confirm or fill in.
A3: As-of date | B3: 46301
A4: Fee check amounts - all entities (inputs) | C4: 644 | D4: 1044 | E4: 69 | F4: 595 | G4: 995 | H4: 49 | I4: 110
A5: Additional fee amounts - Philly only (inputs) | C5: 495 | D5: 295
A6: Additional fee amounts - TUR only (inputs) | C6: 150 | D6: 250 | E6: 350 | F6: 450 | G6: 60 | H6: 179
A7: Small-amount threshold | B7: 250
A9: Entity | B9: State (confirm) | C9: Prior-month accrued (unbooked deposits) | D9: Current-month accrued (Sept/Oct 2026 deposits) | E9: Total accrued per workbook | F9: Items (count) | G9: 0-1 yrs | H9: 1-2 yrs | I9: 2-3 yrs | J9: 3-5 yrs | K9: 5+ yrs | L9: $ at fee amounts (presumed company revenue) | M9: $ small amounts (likely fee, review) | N9: $ memo-flagged (not ours / unknown / hold) | O9: $ larger amounts (likely includes agent commission) | P9: Short period (yrs) | Q9: Long period (yrs) | R9: Dormant today - SHORT test - ALL items | S9: Dormant today - LONG test - ALL items | T9: Dormant today - SHORT test - likely-commission + memo-flagged only | U9: Dormant today - LONG test - likely-commission + memo-flagged only | V9: Dormant at next report cutoff - SHORT - likely-commission + memo-flagged | W9: Dormant at next report cutoff - LONG - likely-commission + memo-flagged | X9: Likely test given independent-contractor agents | Y9: Dormant today - LIKELY test - likely-commission + memo-flagged | Z9: Dormant at next report cutoff - LIKELY test - likely-commission + memo-flagged | AA9: Oldest item | AB9: Entity-state note
A10: Dallas | B10: TX | C10: =SUMIFS(Detail!$H:$H,Detail!$A:$A,$A10) -> 59991.62 | D10: =SUMIFS('Current Month'!$F:$F,'Current Month'!$A:$A,$A10) -> 15586.87 | E10: =C10+D10 -> 75578.49 | F10: =COUNTIFS(Detail!$A:$A,$A10,Detail!$H:$H,"<>") -> 50 | G10: =SUMIFS(Detail!$H:$H,Detail!$A:$A,$A10,Detail!$L:$L,"0-1 yrs") -> 39767.62 | H10: =SUMIFS(Detail!$H:$H,Detail!$A:$A,$A10,Detail!$L:$L,"1-2 yrs") -> 6244.96 | I10: =SUMIFS(Detail!$H:$H,Detail!$A:$A,$A10,Detail!$L:$L,"2-3 yrs") -> 7179.74 | J10: =SUMIFS(Detail!$H:$H,Detail!$A:$A,$A10,Detail!$L:$L,"3-5 yrs") -> 6799.3 | K10: =SUMIFS(Detail!$H:$H,Detail!$A:$A,$A10,Detail!$L:$L,"5+ yrs") -> 0 | L10: =SUMIFS(Detail!$H:$H,Detail!$A:$A,$A10,Detail!$N:$N,"Fee amount*") -> 2401 | M10: =SUMIFS(Detail!$H:$H,Detail!$A:$A,$A10,Detail!$N:$N,"Small amount*") -> 622.08 | N10: =SUMIFS(Detail!$H:$H,Detail!$A:$A,$A10,Detail!$N:$N,"Memo flag*") -> 27321.63 | O10: =SUMIFS(Detail!$H:$H,Detail!$A:$A,$A10,Detail!$N:$N,"Larger amount*") -> 29646.91 | P10: =IFERROR(INDEX('State Rules'!$C$5:$C$11,MATCH($B10,'State Rules'!$A$5:$A$11,0)),"") -> 1 | Q10: =IFERROR(INDEX('State Rules'!$E$5:$E$11,MATCH($B10,'State Rules'!$A$5:$A$11,0)),"") -> 3 | R10: =SUMIFS(Detail!$H:$H,Detail!$A:$A,$A10,Detail!$P:$P,"<="&$B$3) -> 20224 | S10: =SUMIFS(Detail!$H:$H,Detail!$A:$A,$A10,Detail!$Q:$Q,"<="&$B$3) -> 6799.3 | T10: =SUMIFS(Detail!$AA:$AA,Detail!$A:$A,$A10,Detail!$P:$P,"<="&$B$3) -> 17639.54 | U10: =SUMIFS(Detail!$AA:$AA,Detail!$A:$A,$A10,Detail!$Q:$Q,"<="&$B$3) -> 6707.8 | V10: =SUMIFS(Detail!$AA:$AA,Detail!$A:$A,$A10,Detail!$R:$R,"Yes") -> 21952.66 | W10: =SUMIFS(Detail!$AA:$AA,Detail!$A:$A,$A10,Detail!$S:$S,"Yes") -> 8042.3 | X10: =IFERROR(INDEX('State Rules'!$M$5:$M$11,MATCH($B10,'State Rules'!$A$5:$A$11,0)),"") -> LONG | Y10: =IF(X10="SHORT",T10,IF(X10="LONG",U10,0)) -> 6707.8 | Z10: =IF(X10="SHORT",V10,IF(X10="LONG",W10,0)) -> 8042.3 | AA10: =IF(F10=0,"",_xlfn.MINIFS(Detail!$E$7:$E$400,Detail!$A$7:$A$400,$A10)) -> 44988 | AB10: Confirmed by user 10/6/2026: Texas. ICA names 'URE Dallas LLC dba United Real Estate'. State of formation not yet provided.
A11: Houston | B11: TX | C11: =SUMIFS(Detail!$H:$H,Detail!$A:$A,$A11) -> 76889.5 | D11: =SUMIFS('Current Month'!$F:$F,'Current Month'!$A:$A,$A11) -> 10071.93 | E11: =C11+D11 -> 86961.43 | F11: =COUNTIFS(Detail!$A:$A,$A11,Detail!$H:$H,"<>") -> 40 | G11: =SUMIFS(Detail!$H:$H,Detail!$A:$A,$A11,Detail!$L:$L,"0-1 yrs") -> 26416.5 | H11: =SUMIFS(Detail!$H:$H,Detail!$A:$A,$A11,Detail!$L:$L,"1-2 yrs") -> 35650.9 | I11: =SUMIFS(Detail!$H:$H,Detail!$A:$A,$A11,Detail!$L:$L,"2-3 yrs") -> 9185.5 | J11: =SUMIFS(Detail!$H:$H,Detail!$A:$A,$A11,Detail!$L:$L,"3-5 yrs") -> 5636.6 | K11: =SUMIFS(Detail!$H:$H,Detail!$A:$A,$A11,Detail!$L:$L,"5+ yrs") -> 0 | L11: =SUMIFS(Detail!$H:$H,Detail!$A:$A,$A11,Detail!$N:$N,"Fee amount*") -> 3669 | M11: =SUMIFS(Detail!$H:$H,Detail!$A:$A,$A11,Detail!$N:$N,"Small amount*") -> 450 | N11: =SUMIFS(Detail!$H:$H,Detail!$A:$A,$A11,Detail!$N:$N,"Memo flag*") -> 1875 | O11: =SUMIFS(Detail!$H:$H,Detail!$A:$A,$A11,Detail!$N:$N,"Larger amount*") -> 70895.5 | P11: =IFERROR(INDEX('State Rules'!$C$5:$C$11,MATCH($B11,'State Rules'!$A$5:$A$11,0)),"") -> 1 | Q11: =IFERROR(INDEX('State Rules'!$E$5:$E$11,MATCH($B11,'State Rules'!$A$5:$A$11,0)),"") -> 3 | R11: =SUMIFS(Detail!$H:$H,Detail!$A:$A,$A11,Detail!$P:$P,"<="&$B$3) -> 50473 | S11: =SUMIFS(Detail!$H:$H,Detail!$A:$A,$A11,Detail!$Q:$Q,"<="&$B$3) -> 5636.6 | T11: =SUMIFS(Detail!$AA:$AA,Detail!$A:$A,$A11,Detail!$P:$P,"<="&$B$3) -> 48286 | U11: =SUMIFS(Detail!$AA:$AA,Detail!$A:$A,$A11,Detail!$Q:$Q,"<="&$B$3) -> 5636.6 | V11: =SUMIFS(Detail!$AA:$AA,Detail!$A:$A,$A11,Detail!$R:$R,"Yes") -> 49136 | W11: =SUMIFS(Detail!$AA:$AA,Detail!$A:$A,$A11,Detail!$S:$S,"Yes") -> 6011.6 | X11: =IFERROR(INDEX('State Rules'!$M$5:$M$11,MATCH($B11,'State Rules'!$A$5:$A$11,0)),"") -> LONG | Y11: =IF(X11="SHORT",T11,IF(X11="LONG",U11,0)) -> 5636.6 | Z11: =IF(X11="SHORT",V11,IF(X11="LONG",W11,0)) -> 6011.6 | AA11: =IF(F11=0,"",_xlfn.MINIFS(Detail!$E$7:$E$400,Detail!$A$7:$A$400,$A11)) -> 44592 | AB11: Confirmed by user 10/6/2026: Texas. ICA names 'URE Houston LLC d/b/a United Real Estate'. State of formation not yet provided.
A12: TUR | B12: TX | C12: =SUMIFS(Detail!$H:$H,Detail!$A:$A,$A12) -> 55528.45 | D12: =SUMIFS('Current Month'!$F:$F,'Current Month'!$A:$A,$A12) -> 20054.2 | E12: =C12+D12 -> 75582.65 | F12: =COUNTIFS(Detail!$A:$A,$A12,Detail!$H:$H,"<>") -> 50 | G12: =SUMIFS(Detail!$H:$H,Detail!$A:$A,$A12,Detail!$L:$L,"0-1 yrs") -> 34473 | H12: =SUMIFS(Detail!$H:$H,Detail!$A:$A,$A12,Detail!$L:$L,"1-2 yrs") -> 5539.51 | I12: =SUMIFS(Detail!$H:$H,Detail!$A:$A,$A12,Detail!$L:$L,"2-3 yrs") -> 13657.94 | J12: =SUMIFS(Detail!$H:$H,Detail!$A:$A,$A12,Detail!$L:$L,"3-5 yrs") -> 1858 | K12: =SUMIFS(Detail!$H:$H,Detail!$A:$A,$A12,Detail!$L:$L,"5+ yrs") -> 0 | L12: =SUMIFS(Detail!$H:$H,Detail!$A:$A,$A12,Detail!$N:$N,"Fee amount*") -> 5684 | M12: =SUMIFS(Detail!$H:$H,Detail!$A:$A,$A12,Detail!$N:$N,"Small amount*") -> 1034.25 | N12: =SUMIFS(Detail!$H:$H,Detail!$A:$A,$A12,Detail!$N:$N,"Memo flag*") -> 1444 | O12: =SUMIFS(Detail!$H:$H,Detail!$A:$A,$A12,Detail!$N:$N,"Larger amount*") -> 47366.2 | P12: =IFERROR(INDEX('State Rules'!$C$5:$C$11,MATCH($B12,'State Rules'!$A$5:$A$11,0)),"") -> 1 | Q12: =IFERROR(INDEX('State Rules'!$E$5:$E$11,MATCH($B12,'State Rules'!$A$5:$A$11,0)),"") -> 3 | R12: =SUMIFS(Detail!$H:$H,Detail!$A:$A,$A12,Detail!$P:$P,"<="&$B$3) -> 21055.45 | S12: =SUMIFS(Detail!$H:$H,Detail!$A:$A,$A12,Detail!$Q:$Q,"<="&$B$3) -> 1858 | T12: =SUMIFS(Detail!$AA:$AA,Detail!$A:$A,$A12,Detail!$P:$P,"<="&$B$3) -> 14486.2 | U12: =SUMIFS(Detail!$AA:$AA,Detail!$A:$A,$A12,Detail!$Q:$Q,"<="&$B$3) -> 1188 | V12: =SUMIFS(Detail!$AA:$AA,Detail!$A:$A,$A12,Detail!$R:$R,"Yes") -> 15883.7 | W12: =SUMIFS(Detail!$AA:$AA,Detail!$A:$A,$A12,Detail!$S:$S,"Yes") -> 2917.5 | X12: =IFERROR(INDEX('State Rules'!$M$5:$M$11,MATCH($B12,'State Rules'!$A$5:$A$11,0)),"") -> LONG | Y12: =IF(X12="SHORT",T12,IF(X12="LONG",U12,0)) -> 1188 | Z12: =IF(X12="SHORT",V12,IF(X12="LONG",W12,0)) -> 2917.5 | AA12: =IF(F12=0,"",_xlfn.MINIFS(Detail!$E$7:$E$400,Detail!$A$7:$A$400,$A12)) -> 44951 | AB12: Confirmed by user 10/6/2026: Texas. Sign-up docs name 'Quick-Close Properties, LLC dba Texas United Realty' (TREC 599460). State of formation not yet provided.
A13: Chicago | B13: IL | C13: =SUMIFS(Detail!$H:$H,Detail!$A:$A,$A13) -> 0 | D13: =SUMIFS('Current Month'!$F:$F,'Current Month'!$A:$A,$A13) -> 18345 | E13: =C13+D13 -> 18345 | F13: =COUNTIFS(Detail!$A:$A,$A13,Detail!$H:$H,"<>") -> 0 | G13: =SUMIFS(Detail!$H:$H,Detail!$A:$A,$A13,Detail!$L:$L,"0-1 yrs") -> 0 | H13: =SUMIFS(Detail!$H:$H,Detail!$A:$A,$A13,Detail!$L:$L,"1-2 yrs") -> 0 | I13: =SUMIFS(Detail!$H:$H,Detail!$A:$A,$A13,Detail!$L:$L,"2-3 yrs") -> 0 | J13: =SUMIFS(Detail!$H:$H,Detail!$A:$A,$A13,Detail!$L:$L,"3-5 yrs") -> 0 | K13: =SUMIFS(Detail!$H:$H,Detail!$A:$A,$A13,Detail!$L:$L,"5+ yrs") -> 0 | L13: =SUMIFS(Detail!$H:$H,Detail!$A:$A,$A13,Detail!$N:$N,"Fee amount*") -> 0 | M13: =SUMIFS(Detail!$H:$H,Detail!$A:$A,$A13,Detail!$N:$N,"Small amount*") -> 0 | N13: =SUMIFS(Detail!$H:$H,Detail!$A:$A,$A13,Detail!$N:$N,"Memo flag*") -> 0 | O13: =SUMIFS(Detail!$H:$H,Detail!$A:$A,$A13,Detail!$N:$N,"Larger amount*") -> 0 | P13: =IFERROR(INDEX('State Rules'!$C$5:$C$11,MATCH($B13,'State Rules'!$A$5:$A$11,0)),"") -> 1 | Q13: =IFERROR(INDEX('State Rules'!$E$5:$E$11,MATCH($B13,'State Rules'!$A$5:$A$11,0)),"") -> 3 | R13: =SUMIFS(Detail!$H:$H,Detail!$A:$A,$A13,Detail!$P:$P,"<="&$B$3) -> 0 | S13: =SUMIFS(Detail!$H:$H,Detail!$A:$A,$A13,Detail!$Q:$Q,"<="&$B$3) -> 0 | T13: =SUMIFS(Detail!$AA:$AA,Detail!$A:$A,$A13,Detail!$P:$P,"<="&$B$3) -> 0 | U13: =SUMIFS(Detail!$AA:$AA,Detail!$A:$A,$A13,Detail!$Q:$Q,"<="&$B$3) -> 0 | V13: =SUMIFS(Detail!$AA:$AA,Detail!$A:$A,$A13,Detail!$R:$R,"Yes") -> 0 | W13: =SUMIFS(Detail!$AA:$AA,Detail!$A:$A,$A13,Detail!$S:$S,"Yes") -> 0 | X13: =IFERROR(INDEX('State Rules'!$M$5:$M$11,MATCH($B13,'State Rules'!$A$5:$A$11,0)),"") -> SHORT | Y13: =IF(X13="SHORT",T13,IF(X13="LONG",U13,0)) -> 0 | Z13: =IF(X13="SHORT",V13,IF(X13="LONG",W13,0)) -> 0 | AA13: =IF(F13=0,"",_xlfn.MINIFS(Detail!$E$7:$E$400,Detail!$A$7:$A$400,$A13)) | AB13: Confirmed by user 10/6/2026: Illinois. ICA names 'URE Chicago LLC dba United Real Estate - Chicago'. State of formation not yet provided.
A14: Philly | B14: PA | C14: =SUMIFS(Detail!$H:$H,Detail!$A:$A,$A14) -> 29708.78 | D14: =SUMIFS('Current Month'!$F:$F,'Current Month'!$A:$A,$A14) -> 49091.5 | E14: =C14+D14 -> 78800.28 | F14: =COUNTIFS(Detail!$A:$A,$A14,Detail!$H:$H,"<>") -> 34 | G14: =SUMIFS(Detail!$H:$H,Detail!$A:$A,$A14,Detail!$L:$L,"0-1 yrs") -> 8931.12 | H14: =SUMIFS(Detail!$H:$H,Detail!$A:$A,$A14,Detail!$L:$L,"1-2 yrs") -> 10077.25 | I14: =SUMIFS(Detail!$H:$H,Detail!$A:$A,$A14,Detail!$L:$L,"2-3 yrs") -> 10281.06 | J14: =SUMIFS(Detail!$H:$H,Detail!$A:$A,$A14,Detail!$L:$L,"3-5 yrs") -> 419.35 | K14: =SUMIFS(Detail!$H:$H,Detail!$A:$A,$A14,Detail!$L:$L,"5+ yrs") -> 0 | L14: =SUMIFS(Detail!$H:$H,Detail!$A:$A,$A14,Detail!$N:$N,"Fee amount*") -> 6592 | M14: =SUMIFS(Detail!$H:$H,Detail!$A:$A,$A14,Detail!$N:$N,"Small amount*") -> 252 | N14: =SUMIFS(Detail!$H:$H,Detail!$A:$A,$A14,Detail!$N:$N,"Memo flag*") -> 0 | O14: =SUMIFS(Detail!$H:$H,Detail!$A:$A,$A14,Detail!$N:$N,"Larger amount*") -> 22864.78 | P14: =IFERROR(INDEX('State Rules'!$C$5:$C$11,MATCH($B14,'State Rules'!$A$5:$A$11,0)),"") -> 2 | Q14: =IFERROR(INDEX('State Rules'!$E$5:$E$11,MATCH($B14,'State Rules'!$A$5:$A$11,0)),"") -> 3 | R14: =SUMIFS(Detail!$H:$H,Detail!$A:$A,$A14,Detail!$P:$P,"<="&$B$3) -> 10700.41 | S14: =SUMIFS(Detail!$H:$H,Detail!$A:$A,$A14,Detail!$Q:$Q,"<="&$B$3) -> 419.35 | T14: =SUMIFS(Detail!$AA:$AA,Detail!$A:$A,$A14,Detail!$P:$P,"<="&$B$3) -> 8566.41 | U14: =SUMIFS(Detail!$AA:$AA,Detail!$A:$A,$A14,Detail!$Q:$Q,"<="&$B$3) -> 419.35 | V14: =SUMIFS(Detail!$AA:$AA,Detail!$A:$A,$A14,Detail!$R:$R,"Yes") -> 12172.66 | W14: =SUMIFS(Detail!$AA:$AA,Detail!$A:$A,$A14,Detail!$S:$S,"Yes") -> 419.35 | X14: =IFERROR(INDEX('State Rules'!$M$5:$M$11,MATCH($B14,'State Rules'!$A$5:$A$11,0)),"") -> SHORT | Y14: =IF(X14="SHORT",T14,IF(X14="LONG",U14,0)) -> 8566.41 | Z14: =IF(X14="SHORT",V14,IF(X14="LONG",W14,0)) -> 12172.66 | AA14: =IF(F14=0,"",_xlfn.MINIFS(Detail!$E$7:$E$400,Detail!$A$7:$A$400,$A14)) -> 45175 | AB14: Confirmed by user 10/6/2026: Pennsylvania. PA ICA names only 'United Real Estate'; legal entity and state of formation not yet provided.
A15: Gallery | B15: FL | C15: =SUMIFS(Detail!$H:$H,Detail!$A:$A,$A15) -> 4001.11 | D15: =SUMIFS('Current Month'!$F:$F,'Current Month'!$A:$A,$A15) -> 0 | E15: =C15+D15 -> 4001.11 | F15: =COUNTIFS(Detail!$A:$A,$A15,Detail!$H:$H,"<>") -> 4 | G15: =SUMIFS(Detail!$H:$H,Detail!$A:$A,$A15,Detail!$L:$L,"0-1 yrs") -> 4001.11 | H15: =SUMIFS(Detail!$H:$H,Detail!$A:$A,$A15,Detail!$L:$L,"1-2 yrs") -> 0 | I15: =SUMIFS(Detail!$H:$H,Detail!$A:$A,$A15,Detail!$L:$L,"2-3 yrs") -> 0 | J15: =SUMIFS(Detail!$H:$H,Detail!$A:$A,$A15,Detail!$L:$L,"3-5 yrs") -> 0 | K15: =SUMIFS(Detail!$H:$H,Detail!$A:$A,$A15,Detail!$L:$L,"5+ yrs") -> 0 | L15: =SUMIFS(Detail!$H:$H,Detail!$A:$A,$A15,Detail!$N:$N,"Fee amount*") -> 0 | M15: =SUMIFS(Detail!$H:$H,Detail!$A:$A,$A15,Detail!$N:$N,"Small amount*") -> 0 | N15: =SUMIFS(Detail!$H:$H,Detail!$A:$A,$A15,Detail!$N:$N,"Memo flag*") -> 0 | O15: =SUMIFS(Detail!$H:$H,Detail!$A:$A,$A15,Detail!$N:$N,"Larger amount*") -> 4001.11 | P15: =IFERROR(INDEX('State Rules'!$C$5:$C$11,MATCH($B15,'State Rules'!$A$5:$A$11,0)),"") -> 1 | Q15: =IFERROR(INDEX('State Rules'!$E$5:$E$11,MATCH($B15,'State Rules'!$A$5:$A$11,0)),"") -> 5 | R15: =SUMIFS(Detail!$H:$H,Detail!$A:$A,$A15,Detail!$P:$P,"<="&$B$3) -> 0 | S15: =SUMIFS(Detail!$H:$H,Detail!$A:$A,$A15,Detail!$Q:$Q,"<="&$B$3) -> 0 | T15: =SUMIFS(Detail!$AA:$AA,Detail!$A:$A,$A15,Detail!$P:$P,"<="&$B$3) -> 0 | U15: =SUMIFS(Detail!$AA:$AA,Detail!$A:$A,$A15,Detail!$Q:$Q,"<="&$B$3) -> 0 | V15: =SUMIFS(Detail!$AA:$AA,Detail!$A:$A,$A15,Detail!$R:$R,"Yes") -> 0 | W15: =SUMIFS(Detail!$AA:$AA,Detail!$A:$A,$A15,Detail!$S:$S,"Yes") -> 0 | X15: =IFERROR(INDEX('State Rules'!$M$5:$M$11,MATCH($B15,'State Rules'!$A$5:$A$11,0)),"") -> LONG | Y15: =IF(X15="SHORT",T15,IF(X15="LONG",U15,0)) -> 0 | Z15: =IF(X15="SHORT",V15,IF(X15="LONG",W15,0)) -> 0 | AA15: =IF(F15=0,"",_xlfn.MINIFS(Detail!$E$7:$E$400,Detail!$A$7:$A$400,$A15)) -> 46156 | AB15: Confirmed by user 10/6/2026: Florida. LLC; state of formation not yet provided.
A16: Leading Edge | B16: AL | C16: =SUMIFS(Detail!$H:$H,Detail!$A:$A,$A16) -> 645 | D16: =SUMIFS('Current Month'!$F:$F,'Current Month'!$A:$A,$A16) -> 31392.5 | E16: =C16+D16 -> 32037.5 | F16: =COUNTIFS(Detail!$A:$A,$A16,Detail!$H:$H,"<>") -> 3 | G16: =SUMIFS(Detail!$H:$H,Detail!$A:$A,$A16,Detail!$L:$L,"0-1 yrs") -> 645 | H16: =SUMIFS(Detail!$H:$H,Detail!$A:$A,$A16,Detail!$L:$L,"1-2 yrs") -> 0 | I16: =SUMIFS(Detail!$H:$H,Detail!$A:$A,$A16,Detail!$L:$L,"2-3 yrs") -> 0 | J16: =SUMIFS(Detail!$H:$H,Detail!$A:$A,$A16,Detail!$L:$L,"3-5 yrs") -> 0 | K16: =SUMIFS(Detail!$H:$H,Detail!$A:$A,$A16,Detail!$L:$L,"5+ yrs") -> 0 | L16: =SUMIFS(Detail!$H:$H,Detail!$A:$A,$A16,Detail!$N:$N,"Fee amount*") -> 0 | M16: =SUMIFS(Detail!$H:$H,Detail!$A:$A,$A16,Detail!$N:$N,"Small amount*") -> 250 | N16: =SUMIFS(Detail!$H:$H,Detail!$A:$A,$A16,Detail!$N:$N,"Memo flag*") -> 0 | O16: =SUMIFS(Detail!$H:$H,Detail!$A:$A,$A16,Detail!$N:$N,"Larger amount*") -> 395 | P16: =IFERROR(INDEX('State Rules'!$C$5:$C$11,MATCH($B16,'State Rules'!$A$5:$A$11,0)),"") -> 1 | Q16: =IFERROR(INDEX('State Rules'!$E$5:$E$11,MATCH($B16,'State Rules'!$A$5:$A$11,0)),"") -> 3 | R16: =SUMIFS(Detail!$H:$H,Detail!$A:$A,$A16,Detail!$P:$P,"<="&$B$3) -> 0 | S16: =SUMIFS(Detail!$H:$H,Detail!$A:$A,$A16,Detail!$Q:$Q,"<="&$B$3) -> 0 | T16: =SUMIFS(Detail!$AA:$AA,Detail!$A:$A,$A16,Detail!$P:$P,"<="&$B$3) -> 0 | U16: =SUMIFS(Detail!$AA:$AA,Detail!$A:$A,$A16,Detail!$Q:$Q,"<="&$B$3) -> 0 | V16: =SUMIFS(Detail!$AA:$AA,Detail!$A:$A,$A16,Detail!$R:$R,"Yes") -> 395 | W16: =SUMIFS(Detail!$AA:$AA,Detail!$A:$A,$A16,Detail!$S:$S,"Yes") -> 0 | X16: =IFERROR(INDEX('State Rules'!$M$5:$M$11,MATCH($B16,'State Rules'!$A$5:$A$11,0)),"") -> SHORT | Y16: =IF(X16="SHORT",T16,IF(X16="LONG",U16,0)) -> 0 | Z16: =IF(X16="SHORT",V16,IF(X16="LONG",W16,0)) -> 395 | AA16: =IF(F16=0,"",_xlfn.MINIFS(Detail!$E$7:$E$400,Detail!$A$7:$A$400,$A16)) -> 46113 | AB16: Confirmed by user 10/6/2026: Alabama. LLC; state of formation not yet provided.
A17: DC | B17: DC | C17: =SUMIFS(Detail!$H:$H,Detail!$A:$A,$A17) -> 0 | D17: =SUMIFS('Current Month'!$F:$F,'Current Month'!$A:$A,$A17) -> 0 | E17: =C17+D17 -> 0 | F17: =COUNTIFS(Detail!$A:$A,$A17,Detail!$H:$H,"<>") -> 0 | G17: =SUMIFS(Detail!$H:$H,Detail!$A:$A,$A17,Detail!$L:$L,"0-1 yrs") -> 0 | H17: =SUMIFS(Detail!$H:$H,Detail!$A:$A,$A17,Detail!$L:$L,"1-2 yrs") -> 0 | I17: =SUMIFS(Detail!$H:$H,Detail!$A:$A,$A17,Detail!$L:$L,"2-3 yrs") -> 0 | J17: =SUMIFS(Detail!$H:$H,Detail!$A:$A,$A17,Detail!$L:$L,"3-5 yrs") -> 0 | K17: =SUMIFS(Detail!$H:$H,Detail!$A:$A,$A17,Detail!$L:$L,"5+ yrs") -> 0 | L17: =SUMIFS(Detail!$H:$H,Detail!$A:$A,$A17,Detail!$N:$N,"Fee amount*") -> 0 | M17: =SUMIFS(Detail!$H:$H,Detail!$A:$A,$A17,Detail!$N:$N,"Small amount*") -> 0 | N17: =SUMIFS(Detail!$H:$H,Detail!$A:$A,$A17,Detail!$N:$N,"Memo flag*") -> 0 | O17: =SUMIFS(Detail!$H:$H,Detail!$A:$A,$A17,Detail!$N:$N,"Larger amount*") -> 0 | P17: =IFERROR(INDEX('State Rules'!$C$5:$C$11,MATCH($B17,'State Rules'!$A$5:$A$11,0)),"") -> 0 | Q17: =IFERROR(INDEX('State Rules'!$E$5:$E$11,MATCH($B17,'State Rules'!$A$5:$A$11,0)),"") -> 0 | R17: =SUMIFS(Detail!$H:$H,Detail!$A:$A,$A17,Detail!$P:$P,"<="&$B$3) -> 0 | S17: =SUMIFS(Detail!$H:$H,Detail!$A:$A,$A17,Detail!$Q:$Q,"<="&$B$3) -> 0 | T17: =SUMIFS(Detail!$AA:$AA,Detail!$A:$A,$A17,Detail!$P:$P,"<="&$B$3) -> 0 | U17: =SUMIFS(Detail!$AA:$AA,Detail!$A:$A,$A17,Detail!$Q:$Q,"<="&$B$3) -> 0 | V17: =SUMIFS(Detail!$AA:$AA,Detail!$A:$A,$A17,Detail!$R:$R,"Yes") -> 0 | W17: =SUMIFS(Detail!$AA:$AA,Detail!$A:$A,$A17,Detail!$S:$S,"Yes") -> 0 | X17: =IFERROR(INDEX('State Rules'!$M$5:$M$11,MATCH($B17,'State Rules'!$A$5:$A$11,0)),"") -> 0 | Y17: =IF(X17="SHORT",T17,IF(X17="LONG",U17,0)) -> 0 | Z17: =IF(X17="SHORT",V17,IF(X17="LONG",W17,0)) -> 0 | AA17: =IF(F17=0,"",_xlfn.MINIFS(Detail!$E$7:$E$400,Detail!$A$7:$A$400,$A17)) | AB17: Tab exists in workbook with $0 accrued balance; user did not list DC. No DC rules researched.
A18: TOTAL | C18: =SUM(C10:C17) -> 226764.46 | D18: =SUM(D10:D17) -> 144542 | E18: =SUM(E10:E17) -> 371306.46 | F18: =SUM(F10:F17) -> 181 | G18: =SUM(G10:G17) -> 114234.35 | H18: =SUM(H10:H17) -> 57512.62 | I18: =SUM(I10:I17) -> 40304.24 | J18: =SUM(J10:J17) -> 14713.25 | ... O18: =SUM(O10:O17) -> 175169.5 | R18: =SUM(R10:R17) -> 102452.86 | S18: =SUM(S10:S17) -> 14713.25 | T18: =SUM(T10:T17) -> 88978.15 | U18: =SUM(U10:U17) -> 13951.75 | V18: =SUM(V10:V17) -> 99540.02 | W18: =SUM(W10:W17) -> 17390.75 | Y18: =SUM(Y10:Y17) -> 22098.81 | Z18: =SUM(Z10:Z17) -> 29539.06
A20: How to read this
A21: Classification (Detail col N) uses the fee amounts in rows 4-6 and the threshold in B7: an exact fee amount = presumed company revenue (keep; book to revenue, not unclaimed property). At or under the threshold = likely fee, review. Memo-flagged = memo says not ours / unknown agent / duplicate / legal hold (owed back to the payer or needs resolution). Everything else = larger amount that likely includes an agent's commission split - this is the unclaimed-property population.
A22: Columns R-S apply the dormancy tests to ALL unbooked items (upper bound). Columns T-W apply them only to the likely-commission and memo-flagged items. Even the T-W figures are upper bounds: within a larger check, only the agent's share (typically the check less the company's fee / split) is reportable; the company's share is revenue.
A23: SHORT test = the state's period for wages / compensation for personal services. LONG test = the general catch-all period. Column X picks the likely test per state now that agents are confirmed to be independent contractors (Texas and Florida: LONG; Illinois, Pennsylvania, Alabama: SHORT), and columns Y-Z apply it. See State Rules cols M-N for the reasoning; it is a legal judgment for counsel to confirm.
A24: Unknown agent = second priority rule. The user confirmed that many older checks cannot be tied to an agent. Those items do not become the company's; they are reportable to the state where the holding LLC was formed (still to be provided). If an LLC is formed in its office state, nothing changes; if formed elsewhere (e.g. Missouri or Delaware), that state's rules and report cycle apply to the unknown-owner items.
A25: Current-month accrued (column D) is all September/October 2026 deposits in normal matching workflow. It is included so the total ties to the cash-requirements Summary, but none of it is near any dormancy period.
A26: Nothing here is legal advice. Dormancy periods, report dates and due-diligence rules on the State Rules tab were sourced from statute summaries and state guidance found by web search; the statute pages themselves could not be opened from this session. Have counsel or your unclaimed-property advisor confirm before filing.

Sheet Detail
A1: Unbooked deposited checks - item detail (prior-month accrued commissions block of each entity tab)
A2: Columns A-J are copied from the source workbook. K-S and Z-AA are formulas. T-Y (yellow) are for you to fill in from Paperless Pipeline / Sage: once the agent share is entered, column Z shows the dollar amount that is both dormant (long test) and owed to someone else. Column AA is the heuristic stand-in until then.
A3: Classification (col N) is driven by Summary rows 4-6 (fee amounts, with Philly-only and TUR-only lists) and Summary B7 (small-amount threshold). Col M flags memos that say not ours / unknown agent / duplicate / legal hold / '?'. Classifications are hints, not conclusions.
A4: As-of date (linked) | B4: =Summary!$B$3 -> 46301
A6: Entity | B6: State | C6: Bank / block | D6: Source row | E6: Deposit date | F6: Check # | G6: Payer / check writer | H6: Amount | I6: Memo (source) | J6: Booked in Sage? | K6: Age (yrs) | L6: Age bucket | M6: Memo flag? | N6: Classification | O6: Short period (yrs) | P6: Dormant date - SHORT | Q6: Dormant date - LONG | R6: Dormant at next cutoff - SHORT? | S6: Dormant at next cutoff - LONG? | T6: Agent / owner name (fill in) | U6: Owner last-known state (fill in) | V6: Brokerage fee / E&O share $ (fill in) | W6: Agent share $ (fill in) | X6: Refund to payer $ (fill in) | Y6: Resolution / status (fill in) | Z6: Reportable if dormant (LONG test) = agent + refund share (from fill-in) | AA6: Heuristic reportable population $ (larger-amount + memo-flagged items)
A7: Dallas | B7: =IFERROR(INDEX(Summary!$B$10:$B$17,MATCH($A7,Summary!$A$10:$A$17,0)),"") -> TX | C7: Dallas | D7: 21 | E7: 44988 | F7: 1839 | G7: Jogip Management | H7: 1097.5 | I7: Vera Garza2538 Emmett St-agent hasn’t uploaded docs, emailed again | J7: No | K7: =IF(E7="","",($B$4-E7)/365.25) -> 3.5947981 | L7: =IF(K7="","no date",IF(K7<1,"0-1 yrs",IF(K7<2,"1-2 yrs",IF(K7<3,"2-3 yrs",IF(K7<5,"3-5 yrs","5+ yrs"))))) -> 3-5 yrs | M7: No | N7: =IF(M7="Yes","Memo flag - not ours / unknown / hold: resolve",IF(OR(COUNTIF(Summary!$C$4:$L$4,H7)>0,AND(A7="Philly",COUNTIF(Summary!$C$5:$L$5,H7)>0),AND(A7="TUR",COUNTIF(Summary!$C$6:$L$6,H7)>0)),"Fee amount - presumed company revenue",IF(H7<=Summary!$B$7,"Small amount - likely fee, review","Larger amount - likely includes agent commission"))) -> Larger amount - likely includes agent commission | O7: =IFERROR(INDEX('State Rules'!$C$5:$C$11,MATCH($B7,'State Rules'!$A$5:$A$11,0)),"") -> 1 | P7: =IF(OR(O7="",E7=""),"",EDATE(E7,12*O7)) -> 45354 | Q7: =IF(E7="","",IFERROR(EDATE(E7,12*INDEX('State Rules'!$E$5:$E$11,MATCH($B7,'State Rules'!$A$5:$A$11,0))),"")) -> 46084 | R7: =IF(P7="","",IFERROR(IF(P7<=INDEX('State Rules'!$I$5:$I$11,MATCH($B7,'State Rules'!$A$5:$A$11,0)),"Yes","No"),"")) -> Yes | S7: =IF(Q7="","",IFERROR(IF(Q7<=INDEX('State Rules'!$I$5:$I$11,MATCH($B7,'State Rules'!$A$5:$A$11,0)),"Yes","No"),"")) -> Yes | Z7: =IF(Q7="","",IF(Q7<=$B$4,N(W7)+N(X7),0)) -> 0 | AA7: =IF(OR(LEFT(N7,6)="Larger",LEFT(N7,4)="Memo"),H7,0) -> 1097.5
A8: Dallas | B8: =IFERROR(INDEX(Summary!$B$10:$B$17,MATCH($A8,Summary!$A$10:$A$17,0)),"") -> TX | C8: Dallas | D8: 22 | E8: 45035 | F8: 167928 | G8: Freedom Title | H8: 444 | I8: File 23067608FM-CC | J8: No | K8: =IF(E8="","",($B$4-E8)/365.25) -> 3.4661191 | L8: =IF(K8="","no date",IF(K8<1,"0-1 yrs",IF(K8<2,"1-2 yrs",IF(K8<3,"2-3 yrs",IF(K8<5,"3-5 yrs","5+ yrs"))))) -> 3-5 yrs | M8: No | N8: =IF(M8="Yes","Memo flag - not ours / unknown / hold: resolve",IF(OR(COUNTIF(Summary!$C$4:$L$4,H8)>0,AND(A8="Philly",COUNTIF(Summary!$C$5:$L$5,H8)>0),AND(A8="TUR",COUNTIF(Summary!$C$6:$L$6,H8)>0)),"Fee amount - presumed company revenue",IF(H8<=Summary!$B$7,"Small amount - likely fee, review","Larger amount - likely includes agent commission"))) -> Larger amount - likely includes agent commission | O8: =IFERROR(INDEX('State Rules'!$C$5:$C$11,MATCH($B8,'State Rules'!$A$5:$A$11,0)),"") -> 1 | P8: =IF(OR(O8="",E8=""),"",EDATE(E8,12*O8)) -> 45401 | Q8: =IF(E8="","",IFERROR(EDATE(E8,12*INDEX('State Rules'!$E$5:$E$11,MATCH($B8,'State Rules'!$A$5:$A$11,0))),"")) -> 46131 | R8: =IF(P8="","",IFERROR(IF(P8<=INDEX('State Rules'!$I$5:$I$11,MATCH($B8,'State Rules'!$A$5:$A$11,0)),"Yes","No"),"")) -> Yes | S8: =IF(Q8="","",IFERROR(IF(Q8<=INDEX('State Rules'!$I$5:$I$11,MATCH($B8,'State Rules'!$A$5:$A$11,0)),"Yes","No"),"")) -> Yes | Z8: =IF(Q8="","",IF(Q8<=$B$4,N(W8)+N(X8),0)) -> 0 | AA8: =IF(OR(LEFT(N8,6)="Larger",LEFT(N8,4)="Memo"),H8,0) -> 444
A9: Dallas | B9: =IFERROR(INDEX(Summary!$B$10:$B$17,MATCH($A9,Summary!$A$10:$A$17,0)),"") -> TX | C9: Dallas | D9: 23 | E9: 45051 | F9: 593095968 | G9: Chicago Title of Texas | H9: 2147.5 | J9: No | K9: =IF(E9="","",($B$4-E9)/365.25) -> 3.4223135 | L9: =IF(K9="","no date",IF(K9<1,"0-1 yrs",IF(K9<2,"1-2 yrs",IF(K9<3,"2-3 yrs",IF(K9<5,"3-5 yrs","5+ yrs"))))) -> 3-5 yrs | M9: No | N9: =IF(M9="Yes","Memo flag - not ours / unknown / hold: resolve",IF(OR(COUNTIF(Summary!$C$4:$L$4,H9)>0,AND(A9="Philly",COUNTIF(Summary!$C$5:$L$5,H9)>0),AND(A9="TUR",COUNTIF(Summary!$C$6:$L$6,H9)>0)),"Fee amount - presumed company revenue",IF(H9<=Summary!$B$7,"Small amount - likely fee, review","Larger amount - likely includes agent commission"))) -> Larger amount - likely includes agent commission | O9: =IFERROR(INDEX('State Rules'!$C$5:$C$11,MATCH($B9,'State Rules'!$A$5:$A$11,0)),"") -> 1 | P9: =IF(OR(O9="",E9=""),"",EDATE(E9,12*O9)) -> 45417 | Q9: =IF(E9="","",IFERROR(EDATE(E9,12*INDEX('State Rules'!$E$5:$E$11,MATCH($B9,'State Rules'!$A$5:$A$11,0))),"")) -> 46147 | R9: =IF(P9="","",IFERROR(IF(P9<=INDEX('State Rules'!$I$5:$I$11,MATCH($B9,'State Rules'!$A$5:$A$11,0)),"Yes","No"),"")) -> Yes | S9: =IF(Q9="","",IFERROR(IF(Q9<=INDEX('State Rules'!$I$5:$I$11,MATCH($B9,'State Rules'!$A$5:$A$11,0)),"Yes","No"),"")) -> Yes | Z9: =IF(Q9="","",IF(Q9<=$B$4,N(W9)+N(X9),0)) -> 0 | AA9: =IF(OR(LEFT(N9,6)="Larger",LEFT(N9,4)="Memo"),H9,0) -> 2147.5
A10: Dallas | B10: =IFERROR(INDEX(Summary!$B$10:$B$17,MATCH($A10,Summary!$A$10:$A$17,0)),"") -> TX | C10: Dallas | D10: 24 | E10: 45071 | F10: 15215 | G10: JARA INVESTMENTS INC | H10: 694.68 | J10: No | K10: =IF(E10="","",($B$4-E10)/365.25) -> 3.3675565 | L10: =IF(K10="","no date",IF(K10<1,"0-1 yrs",IF(K10<2,"1-2 yrs",IF(K10<3,"2-3 yrs",IF(K10<5,"3-5 yrs","5+ yrs"))))) -> 3-5 yrs | M10: No | N10: =IF(M10="Yes","Memo flag - not ours / unknown / hold: resolve",IF(OR(COUNTIF(Summary!$C$4:$L$4,H10)>0,AND(A10="Philly",COUNTIF(Summary!$C$5:$L$5,H10)>0),AND(A10="TUR",COUNTIF(Summary!$C$6:$L$6,H10)>0)),"Fee amount - presumed company revenue",IF(H10<=Summary!$B$7,"Small amount - likely fee, review","Larger amount - likely includes agent commission"))) -> Larger amount - likely includes agent commission | O10: =IFERROR(INDEX('State Rules'!$C$5:$C$11,MATCH($B10,'State Rules'!$A$5:$A$11,0)),"") -> 1 | P10: =IF(OR(O10="",E10=""),"",EDATE(E10,12*O10)) -> 45437 | Q10: =IF(E10="","",IFERROR(EDATE(E10,12*INDEX('State Rules'!$E$5:$E$11,MATCH($B10,'State Rules'!$A$5:$A$11,0))),"")) -> 46167 | R10: =IF(P10="","",IFERROR(IF(P10<=INDEX('State Rules'!$I$5:$I$11,MATCH($B10,'State Rules'!$A$5:$A$11,0)),"Yes","No"),"")) -> Yes | S10: =IF(Q10="","",IFERROR(IF(Q10<=INDEX('State Rules'!$I$5:$I$11,MATCH($B10,'State Rules'!$A$5:$A$11,0)),"Yes","No"),"")) -> Yes | Z10: =IF(Q10="","",IF(Q10<=$B$4,N(W10)+N(X10),0)) -> 0 | AA10: =IF(OR(LEFT(N10,6)="Larger",LEFT(N10,4)="Memo"),H10,0) -> 694.68
A11: Dallas | B11: =IFERROR(INDEX(Summary!$B$10:$B$17,MATCH($A11,Summary!$A$10:$A$17,0)),"") -> TX | C11: Dallas | D11: 25 | E11: 45106 | F11: 9478743248 | G11: Jaden International | H11: 500 | I11: 6050 N Central Exp 314-not for this address unsure of address | J11: No | K11: =IF(E11="","",($B$4-E11)/365.25) -> 3.2717317 | L11: =IF(K11="","no date",IF(K11<1,"0-1 yrs",IF(K11<2,"1-2 yrs",IF(K11<3,"2-3 yrs",IF(K11<5,"3-5 yrs","5+ yrs"))))) -> 3-5 yrs | M11: Yes | N11: =IF(M11="Yes","Memo flag - not ours / unknown / hold: resolve",IF(OR(COUNTIF(Summary!$C$4:$L$4,H11)>0,AND(A11="Philly",COUNTIF(Summary!$C$5:$L$5,H11)>0),AND(A11="TUR",COUNTIF(Summary!$C$6:$L$6,H11)>0)),"Fee amount - presumed company revenue",IF(H11<=Summary!$B$7,"Small amount - likely fee, review","Larger amount - likely includes agent commission"))) -> Memo flag - not ours / unknown / hold: resolve | O11: =IFERROR(INDEX('State Rules'!$C$5:$C$11,MATCH($B11,'State Rules'!$A$5:$A$11,0)),"") -> 1 | P11: =IF(OR(O11="",E11=""),"",EDATE(E11,12*O11)) -> 45472 | Q11: =IF(E11="","",IFERROR(EDATE(E11,12*INDEX('State Rules'!$E$5:$E$11,MATCH($B11,'State Rules'!$A$5:$A$11,0))),"")) -> 46202 | R11: =IF(P11="","",IFERROR(IF(P11<=INDEX('State Rules'!$I$5:$I$11,MATCH($B11,'State Rules'!$A$5:$A$11,0)),"Yes","No"),"")) -> Yes | S11: =IF(Q11="","",IFERROR(IF(Q11<=INDEX('State Rules'!$I$5:$I$11,MATCH($B11,'State Rules'!$A$5:$A$11,0)),"Yes","No"),"")) -> Yes | Z11: =IF(Q11="","",IF(Q11<=$B$4,N(W11)+N(X11),0)) -> 0 | AA11: =IF(OR(LEFT(N11,6)="Larger",LEFT(N11,4)="Memo"),H11,0) -> 500
A12: Dallas | B12: =IFERROR(INDEX(Summary!$B$10:$B$17,MATCH($A12,Summary!$A$10:$A$17,0)),"") -> TX | C12: Dallas | D12: 26 | E12: 45152 | F12: 310781 | G12: Colliers International | H12: 824.12 | J12: No | K12: =IF(E12="","",($B$4-E12)/365.25) -> 3.1457906 | L12: =IF(K12="","no date",IF(K12<1,"0-1 yrs",IF(K12<2,"1-2 yrs",IF(K12<3,"2-3 yrs",IF(K12<5,"3-5 yrs","5+ yrs"))))) -> 3-5 yrs | M12: No | N12: =IF(M12="Yes","Memo flag - not ours / unknown / hold: resolve",IF(OR(COUNTIF(Summary!$C$4:$L$4,H12)>0,AND(A12="Philly",COUNTIF(Summary!$C$5:$L$5,H12)>0),AND(A12="TUR",COUNTIF(Summary!$C$6:$L$6,H12)>0)),"Fee amount - presumed company revenue",IF(H12<=Summary!$B$7,"Small amount - likely fee, review","Larger amount - likely includes agent commission"))) -> Larger amount - likely includes agent commission | O12: =IFERROR(INDEX('State Rules'!$C$5:$C$11,MATCH($B12,'State Rules'!$A$5:$A$11,0)),"") -> 1 | P12: =IF(OR(O12="",E12=""),"",EDATE(E12,12*O12)) -> 45518 | Q12: =IF(E12="","",IFERROR(EDATE(E12,12*INDEX('State Rules'!$E$5:$E$11,MATCH($B12,'State Rules'!$A$5:$A$11,0))),"")) -> 46248 | R12: =IF(P12="","",IFERROR(IF(P12<=INDEX('State Rules'!$I$5:$I$11,MATCH($B12,'State Rules'!$A$5:$A$11,0)),"Yes","No"),"")) -> Yes | S12: =IF(Q12="","",IFERROR(IF(Q12<=INDEX('State Rules'!$I$5:$I$11,MATCH($B12,'State Rules'!$A$5:$A$11,0)),"Yes","No"),"")) -> Yes | Z12: =IF(Q12="","",IF(Q12<=$B$4,N(W12)+N(X12),0)) -> 0 | AA12: =IF(OR(LEFT(N12,6)="Larger",LEFT(N12,4)="Memo"),H12,0) -> 824.12
A13: Dallas | B13: =IFERROR(INDEX(Summary!$B$10:$B$17,MATCH($A13,Summary!$A$10:$A$17,0)),"") -> TX | C13: Dallas | D13: 27 | E13: 45176 | F13: 5384 | G13: Roxana Handal | H13: 91.5 | J13: No | K13: =IF(E13="","",($B$4-E13)/365.25) -> 3.0800821 | L13: =IF(K13="","no date",IF(K13<1,"0-1 yrs",IF(K13<2,"1-2 yrs",IF(K13<3,"2-3 yrs",IF(K13<5,"3-5 yrs","5+ yrs"))))) -> 3-5 yrs | M13: No | N13: =IF(M13="Yes","Memo flag - not ours / unknown / hold: resolve",IF(OR(COUNTIF(Summary!$C$4:$L$4,H13)>0,AND(A13="Philly",COUNTIF(Summary!$C$5:$L$5,H13)>0),AND(A13="TUR",COUNTIF(Summary!$C$6:$L$6,H13)>0)),"Fee amount - presumed company revenue",IF(H13<=Summary!$B$7,"Small amount - likely fee, review","Larger amount - likely includes agent commission"))) -> Small amount - likely fee, review | O13: =IFERROR(INDEX('State Rules'!$C$5:$C$11,MATCH($B13,'State Rules'!$A$5:$A$11,0)),"") -> 1 | P13: =IF(OR(O13="",E13=""),"",EDATE(E13,12*O13)) -> 45542 | Q13: =IF(E13="","",IFERROR(EDATE(E13,12*INDEX('State Rules'!$E$5:$E$11,MATCH($B13,'State Rules'!$A$5:$A$11,0))),"")) -> 46272 | R13: =IF(P13="","",IFERROR(IF(P13<=INDEX('State Rules'!$I$5:$I$11,MATCH($B13,'State Rules'!$A$5:$A$11,0)),"Yes","No"),"")) -> Yes | S13: =IF(Q13="","",IFERROR(IF(Q13<=INDEX('State Rules'!$I$5:$I$11,MATCH($B13,'State Rules'!$A$5:$A$11,0)),"Yes","No"),"")) -> Yes | Z13: =IF(Q13="","",IF(Q13<=$B$4,N(W13)+N(X13),0)) -> 0 | AA13: =IF(OR(LEFT(N13,6)="Larger",LEFT(N13,4)="Memo"),H13,0) -> 0
A14: Dallas | B14: =IFERROR(INDEX(Summary!$B$10:$B$17,MATCH($A14,Summary!$A$10:$A$17,0)),"") -> TX | C14: Dallas | D14: 28 | E14: 45183 | F14: 554402 | G14: Soleste West Gables c/o Waterton Residential | H14: 1000 | J14: No | K14: =IF(E14="","",($B$4-E14)/365.25) -> 3.0609172 | L14: =IF(K14="","no date",IF(K14<1,"0-1 yrs",IF(K14<2,"1-2 yrs",IF(K14<3,"2-3 yrs",IF(K14<5,"3-5 yrs","5+ yrs"))))) -> 3-5 yrs | M14: No | N14: =IF(M14="Yes","Memo flag - not ours / unknown / hold: resolve",IF(OR(COUNTIF(Summary!$C$4:$L$4,H14)>0,AND(A14="Philly",COUNTIF(Summary!$C$5:$L$5,H14)>0),AND(A14="TUR",COUNTIF(Summary!$C$6:$L$6,H14)>0)),"Fee amount - presumed company revenue",IF(H14<=Summary!$B$7,"Small amount - likely fee, review","Larger amount - likely includes agent commission"))) -> Larger amount - likely includes agent commission | O14: =IFERROR(INDEX('State Rules'!$C$5:$C$11,MATCH($B14,'State Rules'!$A$5:$A$11,0)),"") -> 1 | P14: =IF(OR(O14="",E14=""),"",EDATE(E14,12*O14)) -> 45549 | Q14: =IF(E14="","",IFERROR(EDATE(E14,12*INDEX('State Rules'!$E$5:$E$11,MATCH($B14,'State Rules'!$A$5:$A$11,0))),"")) -> 46279 | R14: =IF(P14="","",IFERROR(IF(P14<=INDEX('State Rules'!$I$5:$I$11,MATCH($B14,'State Rules'!$A$5:$A$11,0)),"Yes","No"),"")) -> Yes | S14: =IF(Q14="","",IFERROR(IF(Q14<=INDEX('State Rules'!$I$5:$I$11,MATCH($B14,'State Rules'!$A$5:$A$11,0)),"Yes","No"),"")) -> Yes | Z14: =IF(Q14="","",IF(Q14<=$B$4,N(W14)+N(X14),0)) -> 0 | AA14: =IF(OR(LEFT(N14,6)="Larger",LEFT(N14,4)="Memo"),H14,0) -> 1000
A15: Dallas | B15: =IFERROR(INDEX(Summary!$B$10:$B$17,MATCH($A15,Summary!$A$10:$A$17,0)),"") -> TX | C15: Dallas | D15: 29 | E15: 45237 | F15: 158770 | G15: McKnight Title | H15: 800 | J15: No | K15: =IF(E15="","",($B$4-E15)/365.25) -> 2.9130732 | L15: =IF(K15="","no date",IF(K15<1,"0-1 yrs",IF(K15<2,"1-2 yrs",IF(K15<3,"2-3 yrs",IF(K15<5,"3-5 yrs","5+ yrs"))))) -> 2-3 yrs | M15: No | N15: =IF(M15="Yes","Memo flag - not ours / unknown / hold: resolve",IF(OR(COUNTIF(Summary!$C$4:$L$4,H15)>0,AND(A15="Philly",COUNTIF(Summary!$C$5:$L$5,H15)>0),AND(A15="TUR",COUNTIF(Summary!$C$6:$L$6,H15)>0)),"Fee amount - presumed company revenue",IF(H15<=Summary!$B$7,"Small amount - likely fee, review","Larger amount - likely includes agent commission"))) -> Larger amount - likely includes agent commission | O15: =IFERROR(INDEX('State Rules'!$C$5:$C$11,MATCH($B15,'State Rules'!$A$5:$A$11,0)),"") -> 1 | P15: =IF(OR(O15="",E15=""),"",EDATE(E15,12*O15)) -> 45603 | Q15: =IF(E15="","",IFERROR(EDATE(E15,12*INDEX('State Rules'!$E$5:$E$11,MATCH($B15,'State Rules'!$A$5:$A$11,0))),"")) -> 46333 | R15: =IF(P15="","",IFERROR(IF(P15<=INDEX('State Rules'!$I$5:$I$11,MATCH($B15,'State Rules'!$A$5:$A$11,0)),"Yes","No"),"")) -> Yes | S15: =IF(Q15="","",IFERROR(IF(Q15<=INDEX('State Rules'!$I$5:$I$11,MATCH($B15,'State Rules'!$A$5:$A$11,0)),"Yes","No"),"")) -> Yes | Z15: =IF(Q15="","",IF(Q15<=$B$4,N(W15)+N(X15),0)) -> 0 | AA15: =IF(OR(LEFT(N15,6)="Larger",LEFT(N15,4)="Memo"),H15,0) -> 800
A16: Dallas | B16: =IFERROR(INDEX(Summary!$B$10:$B$17,MATCH($A16,Summary!$A$10:$A$17,0)),"") -> TX | C16: Dallas | D16: 30 | E16: 45344 | F16: 7201577987 | G16: Hampton on Jupiter | H16: 534.5 | I16: Summit Property Management | J16: No | K16: =IF(E16="","",($B$4-E16)/365.25) -> 2.6201232 | L16: =IF(K16="","no date",IF(K16<1,"0-1 yrs",IF(K16<2,"1-2 yrs",IF(K16<3,"2-3 yrs",IF(K16<5,"3-5 yrs","5+ yrs"))))) -> 2-3 yrs | M16: No | N16: =IF(M16="Yes","Memo flag - not ours / unknown / hold: resolve",IF(OR(COUNTIF(Summary!$C$4:$L$4,H16)>0,AND(A16="Philly",COUNTIF(Summary!$C$5:$L$5,H16)>0),AND(A16="TUR",COUNTIF(Summary!$C$6:$L$6,H16)>0)),"Fee amount - presumed company revenue",IF(H16<=Summary!$B$7,"Small amount - likely fee, review","Larger amount - likely includes agent commission"))) -> Larger amount - likely includes agent commission | O16: =IFERROR(INDEX('State Rules'!$C$5:$C$11,MATCH($B16,'State Rules'!$A$5:$A$11,0)),"") -> 1 | P16: =IF(OR(O16="",E16=""),"",EDATE(E16,12*O16)) -> 45710 | Q16: =IF(E16="","",IFERROR(EDATE(E16,12*INDEX('State Rules'!$E$5:$E$11,MATCH($B16,'State Rules'!$A$5:$A$11,0))),"")) -> 46440 | R16: =IF(P16="","",IFERROR(IF(P16<=INDEX('State Rules'!$I$5:$I$11,MATCH($B16,'State Rules'!$A$5:$A$11,0)),"Yes","No"),"")) -> Yes | S16: =IF(Q16="","",IFERROR(IF(Q16<=INDEX('State Rules'!$I$5:$I$11,MATCH($B16,'State Rules'!$A$5:$A$11,0)),"Yes","No"),"")) -> Yes | Z16: =IF(Q16="","",IF(Q16<=$B$4,N(W16)+N(X16),0)) -> 0 | AA16: =IF(OR(LEFT(N16,6)="Larger",LEFT(N16,4)="Memo"),H16,0) -> 534.5
A17: Dallas | B17: =IFERROR(INDEX(Summary!$B$10:$B$17,MATCH($A17,Summary!$A$10:$A$17,0)),"") -> TX | C17: Dallas | D17: 31 | E17: 45365 | F17: 3536 | G17: Guildford LLC | H17: 945 | I17: 709 Golden Bear- Junko Cummings- ck 3604 processed with this transaction(duplicate?) | J17: No | K17: =IF(E17="","",($B$4-E17)/365.25) -> 2.5626283 | L17: =IF(K17="","no date",IF(K17<1,"0-1 yrs",IF(K17<2,"1-2 yrs",IF(K17<3,"2-3 yrs",IF(K17<5,"3-5 yrs","5+ yrs"))))) -> 2-3 yrs | M17: Yes | N17: =IF(M17="Yes","Memo flag - not ours / unknown / hold: resolve",IF(OR(COUNTIF(Summary!$C$4:$L$4,H17)>0,AND(A17="Philly",COUNTIF(Summary!$C$5:$L$5,H17)>0),AND(A17="TUR",COUNTIF(Summary!$C$6:$L$6,H17)>0)),"Fee amount - presumed company revenue",IF(H17<=Summary!$B$7,"Small amount - likely fee, review","Larger amount - likely includes agent commission"))) -> Memo flag - not ours / unknown / hold: resolve | O17: =IFERROR(INDEX('State Rules'!$C$5:$C$11,MATCH($B17,'State Rules'!$A$5:$A$11,0)),"") -> 1 | P17: =IF(OR(O17="",E17=""),"",EDATE(E17,12*O17)) -> 45730 | Q17: =IF(E17="","",IFERROR(EDATE(E17,12*INDEX('State Rules'!$E$5:$E$11,MATCH($B17,'State Rules'!$A$5:$A$11,0))),"")) -> 46460 | R17: =IF(P17="","",IFERROR(IF(P17<=INDEX('State Rules'!$I$5:$I$11,MATCH($B17,'State Rules'!$A$5:$A$11,0)),"Yes","No"),"")) -> Yes | S17: =IF(Q17="","",IFERROR(IF(Q17<=INDEX('State Rules'!$I$5:$I$11,MATCH($B17,'State Rules'!$A$5:$A$11,0)),"Yes","No"),"")) -> No | Z17: =IF(Q17="","",IF(Q17<=$B$4,N(W17)+N(X17),0)) -> 0 | AA17: =IF(OR(LEFT(N17,6)="Larger",LEFT(N17,4)="Memo"),H17,0) -> 945
A18: Dallas | B18: =IFERROR(INDEX(Summary!$B$10:$B$17,MATCH($A18,Summary!$A$10:$A$17,0)),"") -> TX | C18: Dallas | D18: 32 | E18: 45379 | F18: 7725 | G18: Go Spring Branch | H18: 1000 | I18: 1311 12th St- Lease | J18: No | K18: =IF(E18="","",($B$4-E18)/365.25) -> 2.5242984 | L18: =IF(K18="","no date",IF(K18<1,"0-1 yrs",IF(K18<2,"1-2 yrs",IF(K18<3,"2-3 yrs",IF(K18<5,"3-5 yrs","5+ yrs"))))) -> 2-3 yrs | M18: No | N18: =IF(M18="Yes","Memo flag - not ours / unknown / hold: resolve",IF(OR(COUNTIF(Summary!$C$4:$L$4,H18)>0,AND(A18="Philly",COUNTIF(Summary!$C$5:$L$5,H18)>0),AND(A18="TUR",COUNTIF(Summary!$C$6:$L$6,H18)>0)),"Fee amount - presumed company revenue",IF(H18<=Summary!$B$7,"Small amount - likely fee, review","Larger amount - likely includes agent commission"))) -> Larger amount - likely includes agent commission | O18: =IFERROR(INDEX('State Rules'!$C$5:$C$11,MATCH($B18,'State Rules'!$A$5:$A$11,0)),"") -> 1 | P18: =IF(OR(O18="",E18=""),"",EDATE(E18,12*O18)) -> 45744 | Q18: =IF(E18="","",IFERROR(EDATE(E18,12*INDEX('State Rules'!$E$5:$E$11,MATCH($B18,'State Rules'!$A$5:$A$11,0))),"")) -> 46474 | R18: =IF(P18="","",IFERROR(IF(P18<=INDEX('State Rules'!$I$5:$I$11,MATCH($B18,'State Rules'!$A$5:$A$11,0)),"Yes","No"),"")) -> Yes | S18: =IF(Q18="","",IFERROR(IF(Q18<=INDEX('State Rules'!$I$5:$I$11,MATCH($B18,'State Rules'!$A$5:$A$11,0)),"Yes","No"),"")) -> No | Z18: =IF(Q18="","",IF(Q18<=$B$4,N(W18)+N(X18),0)) -> 0 | AA18: =IF(OR(LEFT(N18,6)="Larger",LEFT(N18,4)="Memo"),H18,0) -> 1000
A19: Dallas | B19: =IFERROR(INDEX(Summary!$B$10:$B$17,MATCH($A19,Summary!$A$10:$A$17,0)),"") -> TX | C19: Dallas | D19: 33 | E19: 45450 | F19: 22833 | H19: 44 | I19: 5740 Cutler Ln- waiting to hear back from title about missing portion | J19: No | K19: =IF(E19="","",($B$4-E19)/365.25) -> 2.329911 | L19: =IF(K19="","no date",IF(K19<1,"0-1 yrs",IF(K19<2,"1-2 yrs",IF(K19<3,"2-3 yrs",IF(K19<5,"3-5 yrs","5+ yrs"))))) -> 2-3 yrs | M19: No | N19: =IF(M19="Yes","Memo flag - not ours / unknown / hold: resolve",IF(OR(COUNTIF(Summary!$C$4:$L$4,H19)>0,AND(A19="Philly",COUNTIF(Summary!$C$5:$L$5,H19)>0),AND(A19="TUR",COUNTIF(Summary!$C$6:$L$6,H19)>0)),"Fee amount - presumed company revenue",IF(H19<=Summary!$B$7,"Small amount - likely fee, review","Larger amount - likely includes agent commission"))) -> Small amount - likely fee, review | O19: =IFERROR(INDEX('State Rules'!$C$5:$C$11,MATCH($B19,'State Rules'!$A$5:$A$11,0)),"") -> 1 | P19: =IF(OR(O19="",E19=""),"",EDATE(E19,12*O19)) -> 45815 | Q19: =IF(E19="","",IFERROR(EDATE(E19,12*INDEX('State Rules'!$E$5:$E$11,MATCH($B19,'State Rules'!$A$5:$A$11,0))),"")) -> 46545 | R19: =IF(P19="","",IFERROR(IF(P19<=INDEX('State Rules'!$I$5:$I$11,MATCH($B19,'State Rules'!$A$5:$A$11,0)),"Yes","No"),"")) -> Yes | S19: =IF(Q19="","",IFERROR(IF(Q19<=INDEX('State Rules'!$I$5:$I$11,MATCH($B19,'State Rules'!$A$5:$A$11,0)),"Yes","No"),"")) -> No | Z19: =IF(Q19="","",IF(Q19<=$B$4,N(W19)+N(X19),0)) -> 0 | AA19: =IF(OR(LEFT(N19,6)="Larger",LEFT(N19,4)="Memo"),H19,0) -> 0
A20: Dallas | B20: =IFERROR(INDEX(Summary!$B$10:$B$17,MATCH($A20,Summary!$A$10:$A$17,0)),"") -> TX | C20: Dallas | D20: 34 | E20: 45476 | F20: 3399 | G20: Texas Title Escrow Account | H20: 10 | J20: No | K20: =IF(E20="","",($B$4-E20)/365.25) -> 2.2587269 | L20: =IF(K20="","no date",IF(K20<1,"0-1 yrs",IF(K20<2,"1-2 yrs",IF(K20<3,"2-3 yrs",IF(K20<5,"3-5 yrs","5+ yrs"))))) -> 2-3 yrs | M20: No | N20: =IF(M20="Yes","Memo flag - not ours / unknown / hold: resolve",IF(OR(COUNTIF(Summary!$C$4:$L$4,H20)>0,AND(A20="Philly",COUNTIF(Summary!$C$5:$L$5,H20)>0),AND(A20="TUR",COUNTIF(Summary!$C$6:$L$6,H20)>0)),"Fee amount - presumed company revenue",IF(H20<=Summary!$B$7,"Small amount - likely fee, review","Larger amount - likely includes agent commission"))) -> Small amount - likely fee, review | O20: =IFERROR(INDEX('State Rules'!$C$5:$C$11,MATCH($B20,'State Rules'!$A$5:$A$11,0)),"") -> 1 | P20: =IF(OR(O20="",E20=""),"",EDATE(E20,12*O20)) -> 45841 | Q20: =IF(E20="","",IFERROR(EDATE(E20,12*INDEX('State Rules'!$E$5:$E$11,MATCH($B20,'State Rules'!$A$5:$A$11,0))),"")) -> 46571 | R20: =IF(P20="","",IFERROR(IF(P20<=INDEX('State Rules'!$I$5:$I$11,MATCH($B20,'State Rules'!$A$5:$A$11,0)),"Yes","No"),"")) -> Yes | S20: =IF(Q20="","",IFERROR(IF(Q20<=INDEX('State Rules'!$I$5:$I$11,MATCH($B20,'State Rules'!$A$5:$A$11,0)),"Yes","No"),"")) -> No | Z20: =IF(Q20="","",IF(Q20<=$B$4,N(W20)+N(X20),0)) -> 0 | AA20: =IF(OR(LEFT(N20,6)="Larger",LEFT(N20,4)="Memo"),H20,0) -> 0
A21: Dallas | B21: =IFERROR(INDEX(Summary!$B$10:$B$17,MATCH($A21,Summary!$A$10:$A$17,0)),"") -> TX | C21: Dallas | D21: 35 | E21: 45476 | F21: 3409 | G21: Texas Title Escrow Account | H21: 1549 | J21: No | K21: =IF(E21="","",($B$4-E21)/365.25) -> 2.2587269 | L21: =IF(K21="","no date",IF(K21<1,"0-1 yrs",IF(K21<2,"1-2 yrs",IF(K21<3,"2-3 yrs",IF(K21<5,"3-5 yrs","5+ yrs"))))) -> 2-3 yrs | M21: No | N21: =IF(M21="Yes","Memo flag - not ours / unknown / hold: resolve",IF(OR(COUNTIF(Summary!$C$4:$L$4,H21)>0,AND(A21="Philly",COUNTIF(Summary!$C$5:$L$5,H21)>0),AND(A21="TUR",COUNTIF(Summary!$C$6:$L$6,H21)>0)),"Fee amount - presumed company revenue",IF(H21<=Summary!$B$7,"Small amount - likely fee, review","Larger amount - likely includes agent commission"))) -> Larger amount - likely includes agent commission | O21: =IFERROR(INDEX('State Rules'!$C$5:$C$11,MATCH($B21,'State Rules'!$A$5:$A$11,0)),"") -> 1 | P21: =IF(OR(O21="",E21=""),"",EDATE(E21,12*O21)) -> 45841 | Q21: =IF(E21="","",IFERROR(EDATE(E21,12*INDEX('State Rules'!$E$5:$E$11,MATCH($B21,'State Rules'!$A$5:$A$11,0))),"")) -> 46571 | R21: =IF(P21="","",IFERROR(IF(P21<=INDEX('State Rules'!$I$5:$I$11,MATCH($B21,'State Rules'!$A$5:$A$11,0)),"Yes","No"),"")) -> Yes | S21: =IF(Q21="","",IFERROR(IF(Q21<=INDEX('State Rules'!$I$5:$I$11,MATCH($B21,'State Rules'!$A$5:$A$11,0)),"Yes","No"),"")) -> No | Z21: =IF(Q21="","",IF(Q21<=$B$4,N(W21)+N(X21),0)) -> 0 | AA21: =IF(OR(LEFT(N21,6)="Larger",LEFT(N21,4)="Memo"),H21,0) -> 1549
A22: Dallas | B22: =IFERROR(INDEX(Summary!$B$10:$B$17,MATCH($A22,Summary!$A$10:$A$17,0)),"") -> TX | C22: Dallas | D22: 36 | E22: 45485 | F22: 36710 | G22: TC Lincoln Centre- Cushman & Wakefield | H22: 609.24 | J22: No | K22: =IF(E22="","",($B$4-E22)/365.25) -> 2.2340862 | L22: =IF(K22="","no date",IF(K22<1,"0-1 yrs",IF(K22<2,"1-2 yrs",IF(K22<3,"2-3 yrs",IF(K22<5,"3-5 yrs","5+ yrs"))))) -> 2-3 yrs | M22: No | N22: =IF(M22="Yes","Memo flag - not ours / unknown / hold: resolve",IF(OR(COUNTIF(Summary!$C$4:$L$4,H22)>0,AND(A22="Philly",COUNTIF(Summary!$C$5:$L$5,H22)>0),AND(A22="TUR",COUNTIF(Summary!$C$6:$L$6,H22)>0)),"Fee amount - presumed company revenue",IF(H22<=Summary!$B$7,"Small amount - likely fee, review","Larger amount - likely includes agent commission"))) -> Larger amount - likely includes agent commission | O22: =IFERROR(INDEX('State Rules'!$C$5:$C$11,MATCH($B22,'State Rules'!$A$5:$A$11,0)),"") -> 1 | P22: =IF(OR(O22="",E22=""),"",EDATE(E22,12*O22)) -> 45850 | Q22: =IF(E22="","",IFERROR(EDATE(E22,12*INDEX('State Rules'!$E$5:$E$11,MATCH($B22,'State Rules'!$A$5:$A$11,0))),"")) -> 46580 | R22: =IF(P22="","",IFERROR(IF(P22<=INDEX('State Rules'!$I$5:$I$11,MATCH($B22,'State Rules'!$A$5:$A$11,0)),"Yes","No"),"")) -> Yes | S22: =IF(Q22="","",IFERROR(IF(Q22<=INDEX('State Rules'!$I$5:$I$11,MATCH($B22,'State Rules'!$A$5:$A$11,0)),"Yes","No"),"")) -> No | Z22: =IF(Q22="","",IF(Q22<=$B$4,N(W22)+N(X22),0)) -> 0 | AA22: =IF(OR(LEFT(N22,6)="Larger",LEFT(N22,4)="Memo"),H22,0) -> 609.24
A23: Dallas | B23: =IFERROR(INDEX(Summary!$B$10:$B$17,MATCH($A23,Summary!$A$10:$A$17,0)),"") -> TX | C23: Dallas | D23: 37 | E23: 45488 | F23: 30197 | G23: Diversified National Title | H23: 644 | J23: No | K23: =IF(E23="","",($B$4-E23)/365.25) -> 2.2258727 | L23: =IF(K23="","no date",IF(K23<1,"0-1 yrs",IF(K23<2,"1-2 yrs",IF(K23<3,"2-3 yrs",IF(K23<5,"3-5 yrs","5+ yrs"))))) -> 2-3 yrs | M23: No | N23: =IF(M23="Yes","Memo flag - not ours / unknown / hold: resolve",IF(OR(COUNTIF(Summary!$C$4:$L$4,H23)>0,AND(A23="Philly",COUNTIF(Summary!$C$5:$L$5,H23)>0),AND(A23="TUR",COUNTIF(Summary!$C$6:$L$6,H23)>0)),"Fee amount - presumed company revenue",IF(H23<=Summary!$B$7,"Small amount - likely fee, review","Larger amount - likely includes agent commission"))) -> Fee amount - presumed company revenue | O23: =IFERROR(INDEX('State Rules'!$C$5:$C$11,MATCH($B23,'State Rules'!$A$5:$A$11,0)),"") -> 1 | P23: =IF(OR(O23="",E23=""),"",EDATE(E23,12*O23)) -> 45853 | Q23: =IF(E23="","",IFERROR(EDATE(E23,12*INDEX('State Rules'!$E$5:$E$11,MATCH($B23,'State Rules'!$A$5:$A$11,0))),"")) -> 46583 | R23: =IF(P23="","",IFERROR(IF(P23<=INDEX('State Rules'!$I$5:$I$11,MATCH($B23,'State Rules'!$A$5:$A$11,0)),"Yes","No"),"")) -> Yes | S23: =IF(Q23="","",IFERROR(IF(Q23<=INDEX('State Rules'!$I$5:$I$11,MATCH($B23,'State Rules'!$A$5:$A$11,0)),"Yes","No"),"")) -> No | Z23: =IF(Q23="","",IF(Q23<=$B$4,N(W23)+N(X23),0)) -> 0 | AA23: =IF(OR(LEFT(N23,6)="Larger",LEFT(N23,4)="Memo"),H23,0) -> 0
A24: Dallas | B24: =IFERROR(INDEX(Summary!$B$10:$B$17,MATCH($A24,Summary!$A$10:$A$17,0)),"") -> TX | C24: Dallas | D24: 38 | E24: 45506 | F24: 103232 | H24: 1044 | J24: No | K24: =IF(E24="","",($B$4-E24)/365.25) -> 2.1765914 | L24: =IF(K24="","no date",IF(K24<1,"0-1 yrs",IF(K24<2,"1-2 yrs",IF(K24<3,"2-3 yrs",IF(K24<5,"3-5 yrs","5+ yrs"))))) -> 2-3 yrs | M24: No | N24: =IF(M24="Yes","Memo flag - not ours / unknown / hold: resolve",IF(OR(COUNTIF(Summary!$C$4:$L$4,H24)>0,AND(A24="Philly",COUNTIF(Summary!$C$5:$L$5,H24)>0),AND(A24="TUR",COUNTIF(Summary!$C$6:$L$6,H24)>0)),"Fee amount - presumed company revenue",IF(H24<=Summary!$B$7,"Small amount - likely fee, review","Larger amount - likely includes agent commission"))) -> Fee amount - presumed company revenue | O24: =IFERROR(INDEX('State Rules'!$C$5:$C$11,MATCH($B24,'State Rules'!$A$5:$A$11,0)),"") -> 1 | P24: =IF(OR(O24="",E24=""),"",EDATE(E24,12*O24)) -> 45871 | Q24: =IF(E24="","",IFERROR(EDATE(E24,12*INDEX('State Rules'!$E$5:$E$11,MATCH($B24,'State Rules'!$A$5:$A$11,0))),"")) -> 46601 | R24: =IF(P24="","",IFERROR(IF(P24<=INDEX('State Rules'!$I$5:$I$11,MATCH($B24,'State Rules'!$A$5:$A$11,0)),"Yes","No"),"")) -> Yes | S24: =IF(Q24="","",IFERROR(IF(Q24<=INDEX('State Rules'!$I$5:$I$11,MATCH($B24,'State Rules'!$A$5:$A$11,0)),"Yes","No"),"")) -> No | Z24: =IF(Q24="","",IF(Q24<=$B$4,N(W24)+N(X24),0)) -> 0 | AA24: =IF(OR(LEFT(N24,6)="Larger",LEFT(N24,4)="Memo"),H24,0) -> 0
A25: Dallas | B25: =IFERROR(INDEX(Summary!$B$10:$B$17,MATCH($A25,Summary!$A$10:$A$17,0)),"") -> TX | C25: Dallas | D25: 39 | E25: 45579 | F25: CK 3000000008 | H25: 449.75 | I25: 2304 Magnolia-Not in PP, not sure who agent is | J25: No | K25: =IF(E25="","",($B$4-E25)/365.25) -> 1.9767283 | L25: =IF(K25="","no date",IF(K25<1,"0-1 yrs",IF(K25<2,"1-2 yrs",IF(K25<3,"2-3 yrs",IF(K25<5,"3-5 yrs","5+ yrs"))))) -> 1-2 yrs | M25: Yes | N25: =IF(M25="Yes","Memo flag - not ours / unknown / hold: resolve",IF(OR(COUNTIF(Summary!$C$4:$L$4,H25)>0,AND(A25="Philly",COUNTIF(Summary!$C$5:$L$5,H25)>0),AND(A25="TUR",COUNTIF(Summary!$C$6:$L$6,H25)>0)),"Fee amount - presumed company revenue",IF(H25<=Summary!$B$7,"Small amount - likely fee, review","Larger amount - likely includes agent commission"))) -> Memo flag - not ours / unknown / hold: resolve | O25: =IFERROR(INDEX('State Rules'!$C$5:$C$11,MATCH($B25,'State Rules'!$A$5:$A$11,0)),"") -> 1 | P25: =IF(OR(O25="",E25=""),"",EDATE(E25,12*O25)) -> 45944 | Q25: =IF(E25="","",IFERROR(EDATE(E25,12*INDEX('State Rules'!$E$5:$E$11,MATCH($B25,'State Rules'!$A$5:$A$11,0))),"")) -> 46674 | R25: =IF(P25="","",IFERROR(IF(P25<=INDEX('State Rules'!$I$5:$I$11,MATCH($B25,'State Rules'!$A$5:$A$11,0)),"Yes","No"),"")) -> Yes | S25: =IF(Q25="","",IFERROR(IF(Q25<=INDEX('State Rules'!$I$5:$I$11,MATCH($B25,'State Rules'!$A$5:$A$11,0)),"Yes","No"),"")) -> No | Z25: =IF(Q25="","",IF(Q25<=$B$4,N(W25)+N(X25),0)) -> 0 | AA25: =IF(OR(LEFT(N25,6)="Larger",LEFT(N25,4)="Memo"),H25,0) -> 449.75
A26: Dallas | B26: =IFERROR(INDEX(Summary!$B$10:$B$17,MATCH($A26,Summary!$A$10:$A$17,0)),"") -> TX | C26: Dallas | D26: 40 | E26: 45611 | F26: CK 14122 | H26: 800 | I26: 5322 Columbia Ave (their transaction #059210-A)-Not in PP | J26: No | K26: =IF(E26="","",($B$4-E26)/365.25) -> 1.889117 | L26: =IF(K26="","no date",IF(K26<1,"0-1 yrs",IF(K26<2,"1-2 yrs",IF(K26<3,"2-3 yrs",IF(K26<5,"3-5 yrs","5+ yrs"))))) -> 1-2 yrs | M26: Yes | N26: =IF(M26="Yes","Memo flag - not ours / unknown / hold: resolve",IF(OR(COUNTIF(Summary!$C$4:$L$4,H26)>0,AND(A26="Philly",COUNTIF(Summary!$C$5:$L$5,H26)>0),AND(A26="TUR",COUNTIF(Summary!$C$6:$L$6,H26)>0)),"Fee amount - presumed company revenue",IF(H26<=Summary!$B$7,"Small amount - likely fee, review","Larger amount - likely includes agent commission"))) -> Memo flag - not ours / unknown / hold: resolve | O26: =IFERROR(INDEX('State Rules'!$C$5:$C$11,MATCH($B26,'State Rules'!$A$5:$A$11,0)),"") -> 1 | P26: =IF(OR(O26="",E26=""),"",EDATE(E26,12*O26)) -> 45976 | Q26: =IF(E26="","",IFERROR(EDATE(E26,12*INDEX('State Rules'!$E$5:$E$11,MATCH($B26,'State Rules'!$A$5:$A$11,0))),"")) -> 46706 | R26: =IF(P26="","",IFERROR(IF(P26<=INDEX('State Rules'!$I$5:$I$11,MATCH($B26,'State Rules'!$A$5:$A$11,0)),"Yes","No"),"")) -> Yes | S26: =IF(Q26="","",IFERROR(IF(Q26<=INDEX('State Rules'!$I$5:$I$11,MATCH($B26,'State Rules'!$A$5:$A$11,0)),"Yes","No"),"")) -> No | Z26: =IF(Q26="","",IF(Q26<=$B$4,N(W26)+N(X26),0)) -> 0 | AA26: =IF(OR(LEFT(N26,6)="Larger",LEFT(N26,4)="Memo"),H26,0) -> 800
A27: Dallas | B27: =IFERROR(INDEX(Summary!$B$10:$B$17,MATCH($A27,Summary!$A$10:$A$17,0)),"") -> TX | C27: Dallas | D27: 41 | E27: 45615 | F27: CK 2704 | H27: 4.5 | I27: 18333 Roehampton- supposed to be for 450 | J27: No | K27: =IF(E27="","",($B$4-E27)/365.25) -> 1.8781656 | L27: =IF(K27="","no date",IF(K27<1,"0-1 yrs",IF(K27<2,"1-2 yrs",IF(K27<3,"2-3 yrs",IF(K27<5,"3-5 yrs","5+ yrs"))))) -> 1-2 yrs | M27: Yes | N27: =IF(M27="Yes","Memo flag - not ours / unknown / hold: resolve",IF(OR(COUNTIF(Summary!$C$4:$L$4,H27)>0,AND(A27="Philly",COUNTIF(Summary!$C$5:$L$5,H27)>0),AND(A27="TUR",COUNTIF(Summary!$C$6:$L$6,H27)>0)),"Fee amount - presumed company revenue",IF(H27<=Summary!$B$7,"Small amount - likely fee, review","Larger amount - likely includes agent commission"))) -> Memo flag - not ours / unknown / hold: resolve | O27: =IFERROR(INDEX('State Rules'!$C$5:$C$11,MATCH($B27,'State Rules'!$A$5:$A$11,0)),"") -> 1 | P27: =IF(OR(O27="",E27=""),"",EDATE(E27,12*O27)) -> 45980 | Q27: =IF(E27="","",IFERROR(EDATE(E27,12*INDEX('State Rules'!$E$5:$E$11,MATCH($B27,'State Rules'!$A$5:$A$11,0))),"")) -> 46710 | R27: =IF(P27="","",IFERROR(IF(P27<=INDEX('State Rules'!$I$5:$I$11,MATCH($B27,'State Rules'!$A$5:$A$11,0)),"Yes","No"),"")) -> Yes | S27: =IF(Q27="","",IFERROR(IF(Q27<=INDEX('State Rules'!$I$5:$I$11,MATCH($B27,'State Rules'!$A$5:$A$11,0)),"Yes","No"),"")) -> No | Z27: =IF(Q27="","",IF(Q27<=$B$4,N(W27)+N(X27),0)) -> 0 | AA27: =IF(OR(LEFT(N27,6)="Larger",LEFT(N27,4)="Memo"),H27,0) -> 4.5
A28: Dallas | B28: =IFERROR(INDEX(Summary!$B$10:$B$17,MATCH($A28,Summary!$A$10:$A$17,0)),"") -> TX | C28: Dallas | D28: 42 | E28: 45616 | F28: CK 5603 | H28: 2865 | I28: The Ashton-not sure of property address or agent | J28: No | K28: =IF(E28="","",($B$4-E28)/365.25) -> 1.8754278 | L28: =IF(K28="","no date",IF(K28<1,"0-1 yrs",IF(K28<2,"1-2 yrs",IF(K28<3,"2-3 yrs",IF(K28<5,"3-5 yrs","5+ yrs"))))) -> 1-2 yrs | M28: Yes | N28: =IF(M28="Yes","Memo flag - not ours / unknown / hold: resolve",IF(OR(COUNTIF(Summary!$C$4:$L$4,H28)>0,AND(A28="Philly",COUNTIF(Summary!$C$5:$L$5,H28)>0),AND(A28="TUR",COUNTIF(Summary!$C$6:$L$6,H28)>0)),"Fee amount - presumed company revenue",IF(H28<=Summary!$B$7,"Small amount - likely fee, review","Larger amount - likely includes agent commission"))) -> Memo flag - not ours / unknown / hold: resolve | O28: =IFERROR(INDEX('State Rules'!$C$5:$C$11,MATCH($B28,'State Rules'!$A$5:$A$11,0)),"") -> 1 | P28: =IF(OR(O28="",E28=""),"",EDATE(E28,12*O28)) -> 45981 | Q28: =IF(E28="","",IFERROR(EDATE(E28,12*INDEX('State Rules'!$E$5:$E$11,MATCH($B28,'State Rules'!$A$5:$A$11,0))),"")) -> 46711 | R28: =IF(P28="","",IFERROR(IF(P28<=INDEX('State Rules'!$I$5:$I$11,MATCH($B28,'State Rules'!$A$5:$A$11,0)),"Yes","No"),"")) -> Yes | S28: =IF(Q28="","",IFERROR(IF(Q28<=INDEX('State Rules'!$I$5:$I$11,MATCH($B28,'State Rules'!$A$5:$A$11,0)),"Yes","No"),"")) -> No | Z28: =IF(Q28="","",IF(Q28<=$B$4,N(W28)+N(X28),0)) -> 0 | AA28: =IF(OR(LEFT(N28,6)="Larger",LEFT(N28,4)="Memo"),H28,0) -> 2865
A29: Dallas | B29: =IFERROR(INDEX(Summary!$B$10:$B$17,MATCH($A29,Summary!$A$10:$A$17,0)),"") -> TX | C29: Dallas | D29: 43 | E29: 45708 | F29: 7005146010 | H29: 106.96 | J29: No | K29: =IF(E29="","",($B$4-E29)/365.25) -> 1.6235455 | L29: =IF(K29="","no date",IF(K29<1,"0-1 yrs",IF(K29<2,"1-2 yrs",IF(K29<3,"2-3 yrs",IF(K29<5,"3-5 yrs","5+ yrs"))))) -> 1-2 yrs | M29: No | N29: =IF(M29="Yes","Memo flag - not ours / unknown / hold: resolve",IF(OR(COUNTIF(Summary!$C$4:$L$4,H29)>0,AND(A29="Philly",COUNTIF(Summary!$C$5:$L$5,H29)>0),AND(A29="TUR",COUNTIF(Summary!$C$6:$L$6,H29)>0)),"Fee amount - presumed company revenue",IF(H29<=Summary!$B$7,"Small amount - likely fee, review","Larger amount - likely includes agent commission"))) -> Small amount - likely fee, review | O29: =IFERROR(INDEX('State Rules'!$C$5:$C$11,MATCH($B29,'State Rules'!$A$5:$A$11,0)),"") -> 1 | P29: =IF(OR(O29="",E29=""),"",EDATE(E29,12*O29)) -> 46073 | Q29: =IF(E29="","",IFERROR(EDATE(E29,12*INDEX('State Rules'!$E$5:$E$11,MATCH($B29,'State Rules'!$A$5:$A$11,0))),"")) -> 46803 | R29: =IF(P29="","",IFERROR(IF(P29<=INDEX('State Rules'!$I$5:$I$11,MATCH($B29,'State Rules'!$A$5:$A$11,0)),"Yes","No"),"")) -> Yes | S29: =IF(Q29="","",IFERROR(IF(Q29<=INDEX('State Rules'!$I$5:$I$11,MATCH($B29,'State Rules'!$A$5:$A$11,0)),"Yes","No"),"")) -> No | Z29: =IF(Q29="","",IF(Q29<=$B$4,N(W29)+N(X29),0)) -> 0 | AA29: =IF(OR(LEFT(N29,6)="Larger",LEFT(N29,4)="Memo"),H29,0) -> 0
A30: Dallas | B30: =IFERROR(INDEX(Summary!$B$10:$B$17,MATCH($A30,Summary!$A$10:$A$17,0)),"") -> TX | C30: Dallas | D30: 44 | E30: 45716 | F30: 37572 | H30: 644 | I30: 1423 Main St. | J30: No | K30: =IF(E30="","",($B$4-E30)/365.25) -> 1.6016427 | L30: =IF(K30="","no date",IF(K30<1,"0-1 yrs",IF(K30<2,"1-2 yrs",IF(K30<3,"2-3 yrs",IF(K30<5,"3-5 yrs","5+ yrs"))))) -> 1-2 yrs | M30: No | N30: =IF(M30="Yes","Memo flag - not ours / unknown / hold: resolve",IF(OR(COUNTIF(Summary!$C$4:$L$4,H30)>0,AND(A30="Philly",COUNTIF(Summary!$C$5:$L$5,H30)>0),AND(A30="TUR",COUNTIF(Summary!$C$6:$L$6,H30)>0)),"Fee amount - presumed company revenue",IF(H30<=Summary!$B$7,"Small amount - likely fee, review","Larger amount - likely includes agent commission"))) -> Fee amount - presumed company revenue | O30: =IFERROR(INDEX('State Rules'!$C$5:$C$11,MATCH($B30,'State Rules'!$A$5:$A$11,0)),"") -> 1 | P30: =IF(OR(O30="",E30=""),"",EDATE(E30,12*O30)) -> 46081 | Q30: =IF(E30="","",IFERROR(EDATE(E30,12*INDEX('State Rules'!$E$5:$E$11,MATCH($B30,'State Rules'!$A$5:$A$11,0))),"")) -> 46811 | R30: =IF(P30="","",IFERROR(IF(P30<=INDEX('State Rules'!$I$5:$I$11,MATCH($B30,'State Rules'!$A$5:$A$11,0)),"Yes","No"),"")) -> Yes | S30: =IF(Q30="","",IFERROR(IF(Q30<=INDEX('State Rules'!$I$5:$I$11,MATCH($B30,'State Rules'!$A$5:$A$11,0)),"Yes","No"),"")) -> No | Z30: =IF(Q30="","",IF(Q30<=$B$4,N(W30)+N(X30),0)) -> 0 | AA30: =IF(OR(LEFT(N30,6)="Larger",LEFT(N30,4)="Memo"),H30,0) -> 0
A31: Dallas | B31: =IFERROR(INDEX(Summary!$B$10:$B$17,MATCH($A31,Summary!$A$10:$A$17,0)),"") -> TX | C31: Dallas | D31: 45 | E31: 45740 | F31: 502001684 | H31: 750 | I31: 3430 Calhoun Ave | J31: No | K31: =IF(E31="","",($B$4-E31)/365.25) -> 1.5359343 | L31: =IF(K31="","no date",IF(K31<1,"0-1 yrs",IF(K31<2,"1-2 yrs",IF(K31<3,"2-3 yrs",IF(K31<5,"3-5 yrs","5+ yrs"))))) -> 1-2 yrs | M31: No | N31: =IF(M31="Yes","Memo flag - not ours / unknown / hold: resolve",IF(OR(COUNTIF(Summary!$C$4:$L$4,H31)>0,AND(A31="Philly",COUNTIF(Summary!$C$5:$L$5,H31)>0),AND(A31="TUR",COUNTIF(Summary!$C$6:$L$6,H31)>0)),"Fee amount - presumed company revenue",IF(H31<=Summary!$B$7,"Small amount - likely fee, review","Larger amount - likely includes agent commission"))) -> Larger amount - likely includes agent commission | O31: =IFERROR(INDEX('State Rules'!$C$5:$C$11,MATCH($B31,'State Rules'!$A$5:$A$11,0)),"") -> 1 | P31: =IF(OR(O31="",E31=""),"",EDATE(E31,12*O31)) -> 46105 | Q31: =IF(E31="","",IFERROR(EDATE(E31,12*INDEX('State Rules'!$E$5:$E$11,MATCH($B31,'State Rules'!$A$5:$A$11,0))),"")) -> 46836 | R31: =IF(P31="","",IFERROR(IF(P31<=INDEX('State Rules'!$I$5:$I$11,MATCH($B31,'State Rules'!$A$5:$A$11,0)),"Yes","No"),"")) -> Yes | S31: =IF(Q31="","",IFERROR(IF(Q31<=INDEX('State Rules'!$I$5:$I$11,MATCH($B31,'State Rules'!$A$5:$A$11,0)),"Yes","No"),"")) -> No | Z31: =IF(Q31="","",IF(Q31<=$B$4,N(W31)+N(X31),0)) -> 0 | AA31: =IF(OR(LEFT(N31,6)="Larger",LEFT(N31,4)="Memo"),H31,0) -> 750
